<?xml version="1.0" encoding="UTF-8"?>
<!-- Generated by org.testng.reporters.JUnitReportReporter -->
<testsuite skipped="3" hostname="KALAMSIR-PC" name="apitests.Test28" tests="8" failures="1" timestamp="2023-04-15T08:59:53 IST" time="6.127" errors="0">
  <testcase name="createUser" time="3.065" classname="apitests.Test28"/>
  <system-out>
    <![CDATA[Successful creation of new user]]>
  </system-out>
  <testcase name="verifyUser" time="0.632" classname="apitests.Test28"/>
  <system-out>
    <![CDATA[false]]>
  </system-out>
  <testcase name="generateToken" time="0.857" classname="apitests.Test28"/>
  <system-out>
    <![CDATA[Successful creation of token]]>
  </system-out>
  <testcase name="addBook" time="0.775" classname="apitests.Test28">
    <failure type="java.lang.AssertionError" message="expected [true] but found [false]">
      <![CDATA[java.lang.AssertionError: expected [true] but found [false]
at org.testng.Assert.fail(Assert.java:99)
at org.testng.Assert.failNotEquals(Assert.java:1037)
at org.testng.Assert.assertTrue(Assert.java:45)
at org.testng.Assert.assertTrue(Assert.java:55)
at apitests.Test28.addBook(Test28.java:115)
at sun.reflect.NativeMethodAccessorImpl.invoke0(Native Method)
at sun.reflect.NativeMethodAccessorImpl.invoke(Unknown Source)
at sun.reflect.DelegatingMethodAccessorImpl.invoke(Unknown Source)
at java.lang.reflect.Method.invoke(Unknown Source)
at org.testng.internal.MethodInvocationHelper.invokeMethod(MethodInvocationHelper.java:133)
at org.testng.internal.TestInvoker.invokeMethod(TestInvoker.java:598)
at org.testng.internal.TestInvoker.invokeTestMethod(TestInvoker.java:173)
at org.testng.internal.MethodRunner.runInSequence(MethodRunner.java:46)
at org.testng.internal.TestInvoker$MethodInvocationAgent.invoke(TestInvoker.java:824)
at org.testng.internal.TestInvoker.invokeTestMethods(TestInvoker.java:146)
at org.testng.internal.TestMethodWorker.invokeTestMethods(TestMethodWorker.java:146)
at org.testng.internal.TestMethodWorker.run(TestMethodWorker.java:128)
at java.util.ArrayList.forEach(Unknown Source)
at org.testng.TestRunner.privateRun(TestRunner.java:794)
at org.testng.TestRunner.run(TestRunner.java:596)
at org.testng.SuiteRunner.runTest(SuiteRunner.java:377)
at org.testng.SuiteRunner.runSequentially(SuiteRunner.java:371)
at org.testng.SuiteRunner.privateRun(SuiteRunner.java:332)
at org.testng.SuiteRunner.run(SuiteRunner.java:276)
at org.testng.SuiteRunnerWorker.runSuite(SuiteRunnerWorker.java:53)
at org.testng.SuiteRunnerWorker.run(SuiteRunnerWorker.java:96)
at org.testng.TestNG.runSuitesSequentially(TestNG.java:1212)
at org.testng.TestNG.runSuitesLocally(TestNG.java:1134)
at org.testng.TestNG.runSuites(TestNG.java:1063)
at org.testng.TestNG.run(TestNG.java:1031)
at org.testng.remote.AbstractRemoteTestNG.run(AbstractRemoteTestNG.java:115)
at org.testng.remote.RemoteTestNG.initAndRun(RemoteTestNG.java:251)
at org.testng.remote.RemoteTestNG.main(RemoteTestNG.java:77)
]]>
    </failure>
  </testcase> <!-- addBook -->
  <system-out>
    <![CDATA[Unsuccessful addition of book to user]]>
  </system-out>
  <testcase name="getBook" time="0.000" classname="apitests.Test28">
    <skipped/>
  </testcase> <!-- getBook -->
  <system-out/>
  <testcase name="updateBook" time="0.000" classname="apitests.Test28">
    <skipped/>
  </testcase> <!-- updateBook -->
  <system-out/>
  <testcase name="deleteBook" time="0.000" classname="apitests.Test28">
    <skipped/>
  </testcase> <!-- deleteBook -->
  <system-out/>
  <testcase name="deleteUser" time="0.798" classname="apitests.Test28"/>
  <system-out>
    <![CDATA[Successful deletion of user]]>
  </system-out>
</testsuite> <!-- apitests.Test28 -->
